<?xml version="1.0"?>
<robot xmlns:xacro="http://ros.org/wiki/xacro">
  <xacro:macro name="abb_irb6700_205_280" params="prefix">
    <xacro:include filename="$(find abb_resources)/urdf/common_materials.xacro"/>
    <!-- link list -->
    <link name="${prefix}base_link">
      <visual>
        <origin xyz="0 0 0" rpy="0 0 0" />
        <geometry>
          <mesh filename="package://abb_irb6700_support/meshes/irb6700/visual/base_link.stl" />
        </geometry>
        <xacro:material_abb_white/>
      </visual>
      <collision>
        <origin xyz="0 0 0" rpy="0 0 0" />
        <geometry>
          <mesh filename="package://abb_irb6700_support/meshes/irb6700/collision/base_link.stl" />
        </geometry>
        <xacro:material_abb_yellow/>
      </collision>
    </link>
    <link name="${prefix}link_1">
      <visual>
        <origin xyz="0 0 0" rpy="0 0 0" />
        <geometry>
          <mesh filename="package://abb_irb6700_support/meshes/irb6700/visual/link_1.stl" />
        </geometry>
        <xacro:material_abb_white/>
      </visual>
      <collision>
        <origin xyz="0 0 0" rpy="0 0 0" />
        <geometry>
          <mesh filename="package://abb_irb6700_support/meshes/irb6700/collision/link_1.stl" />
        </geometry>
        <xacro:material_abb_yellow/>
      </collision>
      <inertial>
        <mass value="319.02" />
        <origin xyz="0.16 0.02 -0.16" rpy="0 0 0"/>
        <inertia ixx="15.99"  ixy="2.57"  ixz="6.95" iyy="25.28" iyz="0.86" izz="21.71"/>
      </inertial>
    </link>
    <link name="${prefix}cylinder">
      <visual>
        <origin xyz="0 0 0" rpy="0 0 0" />
        <geometry>
          <mesh filename="package://abb_irb6700_support/meshes/irb6700/visual/cylinder.stl" />
        </geometry>
        <xacro:material_abb_white/>
      </visual>
      <collision>
        <origin xyz="0 0 0" rpy="0 0 0" />
        <geometry>
          <mesh filename="package://abb_irb6700_support/meshes/irb6700/collision/cylinder.stl" />
        </geometry>
        <xacro:material_abb_yellow/>
      </collision>
    </link>
    <link name="${prefix}piston">
      <visual>
        <origin xyz="0 0 0" rpy="0 0 0" />
        <geometry>
          <mesh filename="package://abb_irb6700_support/meshes/irb6700/visual/piston.stl" />
        </geometry>
        <xacro:material_abb_white/>
      </visual>
      <collision>
        <origin xyz="0 0 0" rpy="0 0 0" />
        <geometry>
          <mesh filename="package://abb_irb6700_support/meshes/irb6700/collision/piston.stl" />
        </geometry>
        <xacro:material_abb_yellow/>
      </collision>
    </link>
    <link name="${prefix}link_2">
      <visual>
        <origin xyz="0.0 0 0" rpy="0 0 0" />
        <geometry>
          <mesh filename="package://abb_irb6700_support/meshes/irb6700_205_280/visual/link_2.stl" />
        </geometry>
        <xacro:material_abb_white/>
      </visual>
      <collision>
        <origin xyz="0 0 0" rpy="0 0 0" />
        <geometry>
          <mesh filename="package://abb_irb6700_support/meshes/irb6700_205_280/collision/link_2.stl" />
        </geometry>
        <xacro:material_abb_yellow/>
      </collision>
      <inertial>
        <mass value="337.83" />
        <origin xyz="0.04 -0.27 0.61" rpy="0 0 0"/>
        <inertia ixx="42.70"  ixy="-0.02"  ixz="-1.37" iyy="44.07" iyz="-3.80" izz="4.67"/>
      </inertial>
    </link>
    <link name="${prefix}link_3">
      <visual>
        <origin xyz="0 0 0" rpy="0 0 0" />
        <geometry>
          <mesh filename="package://abb_irb6700_support/meshes/irb6700_205_280/visual/link_3.stl" />
        </geometry>
        <xacro:material_abb_white/>
      </visual>
      <collision>
        <origin xyz="0 0 0" rpy="0 0 0" />
        <geometry>
          <mesh filename="package://abb_irb6700_support/meshes/irb6700_205_280/collision/link_3.stl" />
        </geometry>
        <xacro:material_abb_yellow/>
      </collision>
      <inertial>
        <mass value="252.97" />
        <origin xyz="-0.06 -0.0 0.13" rpy="0 0 0"/>
        <inertia ixx=" 10.51"  ixy="-1.59"  ixz="-1.12" iyy="8.07" iyz="1.89" izz="10.99"/>
      </inertial>
    </link>
    <link name="${prefix}link_4">
      <visual>
        <origin xyz="0 0 0" rpy="0 0 0" />
        <geometry>
          <mesh filename="package://abb_irb6700_support/meshes/irb6700_205_280/visual/link_4.stl" />
        </geometry>
        <xacro:material_abb_white/>
      </visual>
      <collision>
        <origin xyz="0 0 0" rpy="0 0 0" />
        <geometry>
          <mesh filename="package://abb_irb6700_support/meshes/irb6700_205_280/collision/link_4.stl" />
        </geometry>
        <xacro:material_abb_yellow/>
      </collision>
      <inertial>
        <mass value="271.07" />
        <origin xyz="0.66 -0.01 0.0" rpy="0 0 0"/>
        <inertia ixx=" 3.41"  ixy="-1.37"  ixz="0" iyy="46.90" iyz="0.0" izz="48.53"/>
      </inertial>
    </link>
    <link name="${prefix}link_5">
      <visual>
        <origin xyz="0 0 0" rpy="0 0 0" />
        <geometry>
          <mesh filename="package://abb_irb6700_support/meshes/irb6700/visual/link_5.stl" />
        </geometry>
        <xacro:material_abb_white/>
      </visual>
      <collision>
        <origin xyz="0 0 0" rpy="0 0 0" />
        <geometry>
          <mesh filename="package://abb_irb6700_support/meshes/irb6700/collision/link_5.stl" />
        </geometry>
        <xacro:material_abb_yellow/>
      </collision>
      <inertial>
        <mass value="34.31" />
        <origin xyz="0.02 0.0 0.0" rpy="0 0 0"/>
        <inertia ixx="0.14"  ixy="-0.01"  ixz="-0.01" iyy="0.34" iyz="0.0" izz="0.36"/>
      </inertial>
    </link>
    <link name="${prefix}link_6">
      <visual>
        <origin xyz="0 0 0" rpy="0 0 0" />
        <geometry>
          <mesh filename="package://abb_irb6700_support/meshes/irb6700/visual/link_6.stl" />
        </geometry>
        <xacro:material_abb_white/>
      </visual>
      <collision>
        <origin xyz="0 0 0" rpy="0 0 0" />
        <geometry>
          <mesh filename="package://abb_irb6700_support/meshes/irb6700/collision/link_6.stl" />
        </geometry>
        <xacro:material_abb_yellow/>
      </collision>
      <inertial>
        <mass value="3.57" />
        <origin xyz="-0.02 0.0 0.0" rpy="0 0 0"/>
        <inertia ixx="0.02"  ixy="-0.00"  ixz="-0.00" iyy="0.01" iyz="0.0" izz="0.01"/>
      </inertial>
    </link>

    <joint name="${prefix}joint_1" type="revolute">
      <origin xyz="0 0 0.78" rpy="0 0 0" />
      <parent link="${prefix}base_link" />
      <child link="${prefix}link_1" />
      <axis xyz="0 0 1" />
      <limit lower="-${radians(170)}" upper="${radians(170)}" effort="0" velocity="${radians(110)}" />
    </joint>
    <joint name="${prefix}joint_2" type="revolute">
      <origin xyz="0.32 0 0" rpy="0 0 0" />
      <parent link="${prefix}link_1" />
      <child link="${prefix}link_2" />
      <axis xyz="0 1 0" />
      <limit lower="-${radians(65)}" upper="${radians(85)}" effort="0" velocity="${radians(110)}" />
    </joint>
    <joint name="${prefix}joint_3" type="revolute">
      <origin xyz="0 0 1.280" rpy="0 0 0" />
      <parent link="${prefix}link_2" />
      <child link="${prefix}link_3" />
      <axis xyz="0 1 0" />
      <limit lower="-${radians(180)}" upper="${radians(70)}" effort="0" velocity="${radians(110)}" />
    </joint>
    <joint name="${prefix}joint_4" type="revolute">
      <origin xyz="0 0 0.2" rpy="0 0 0" />
      <parent link="${prefix}link_3" />
      <child link="${prefix}link_4" />
      <axis xyz="1 0 0" />
      <limit lower="-${radians(300)}" upper="${radians(300)}" effort="0" velocity="${radians(190)}" />
    </joint>
    <joint name="${prefix}joint_5" type="revolute">
      <origin xyz="1.1825 0 0" rpy="0 0 0" />
      <parent link="${prefix}link_4" />
      <child link="${prefix}link_5" />
      <axis xyz="0 1 0" />
      <limit lower="-${radians(130)}" upper="${radians(130)}" effort="0" velocity="${radians(150)}" />
    </joint>
    <joint name="${prefix}joint_6" type="revolute">
      <origin xyz="0.2 0 0" rpy="0 0 0" />
      <parent link="${prefix}link_5" />
      <child link="${prefix}link_6" />
      <axis xyz="1 0 0" />
      <limit lower="-${radians(360)}" upper="${radians(360)}" effort="0" velocity="${radians(210)}" />
    </joint>
    <joint name="${prefix}cylinder_joint" type="revolute">
      <origin xyz="-0.349 -0.194 -0.142" rpy="0 0 0" />
      <parent link="${prefix}link_1" />
      <child link="${prefix}cylinder" />
      <axis xyz="0 1 0" />
      <mimic joint="${prefix}joint_2" multiplier="-0.25"/>
      <limit lower="-${radians(65*0.25)}" upper="${radians(85*0.25)}" effort="0" velocity="100" />
    </joint>
    <joint name="${prefix}piston_joint" type="prismatic">
      <origin xyz="0 0 0" rpy="0.20897 0 -${radians(90)}" />
      <parent link="${prefix}cylinder" />
      <child link="${prefix}piston" />
      <axis xyz="0 1 0" />
      <mimic joint="${prefix}joint_2" multiplier="0.15"/>
      <limit lower="-0.25" upper="0.25" effort="0" velocity="100" />
    </joint>

    <!-- ROS-Industrial 'base' frame: base_link to ABB World Coordinates transform -->
    <link name="${prefix}base" />
    <joint name="${prefix}base_link-base" type="fixed">
      <origin xyz="0 0 0" rpy="0 0 0"/>
      <parent link="${prefix}base_link"/>
      <child link="${prefix}base"/>
    </joint>

    <!-- ROS-Industrial 'flange' frame: attachment point for EEF models -->
    <link name="${prefix}flange"/>
    <joint type="fixed" name="${prefix}joint_6-flange">
      <origin xyz="0 0 0" rpy="0 0 0"/>
      <parent link="${prefix}link_6"/>
      <child link="${prefix}flange"/>
    </joint>

    <!-- ROS-Industrial 'tool0' frame: all-zeros tool frame -->
    <link name="${prefix}tool0" />
    <joint name="${prefix}link_6-tool0" type="fixed">
      <origin xyz="0 0 0" rpy="0 ${radians(90)} 0" />
      <parent link="${prefix}flange" />
      <child link="${prefix}tool0" />
    </joint>
  </xacro:macro>
</robot>
